Workbook

Sheet Spese Condivise
A1: SPESE CONDIVISE DA DIVIDERE - Alex & Blake (Ott 2025 - Apr 2026)
A3: AFFITTO
A4: Data | B4: Descrizione | C4: Importo | D4: Fonte | E4: Pagato | F4: Note
A5: 16/10/2025 | B5: Affitto ottobre | C5: 350 | D5: Banca
A6: 17/11/2025 | B6: Affitto novembre | C6: 350 | D6: Banca
A7: 15/12/2025 | B7: Affitto dicembre | C7: 350 | D7: Banca
A8: 15/01/2026 | B8: Affitto gennaio | C8: 350 | D8: Banca
A9: 16/02/2026 | B9: Affitto febbraio | C9: 350 | D9: Banca
A10: 16/03/2026 | B10: Affitto marzo | C10: 350 | D10: Banca
A11: TOTALE | C11: =SUM(C5:C10)
A13: SPESA FISSA MENSILE (100 EUR/mese)
A14: Data | B14: Descrizione | C14: Importo | D14: Fonte | E14: Pagato | F14: Note
A15: 01/10/2025 | B15: Spesa fissa ottobre | C15: 100 | D15: Manuale
A16: 01/11/2025 | B16: Spesa fissa novembre | C16: 100 | D16: Manuale
A17: 01/12/2025 | B17: Spesa fissa dicembre | C17: 100 | D17: Manuale
A18: 01/01/2026 | B18: Spesa fissa gennaio | C18: 100 | D18: Manuale
A19: 01/02/2026 | B19: Spesa fissa febbraio | C19: 100 | D19: Manuale
A20: 01/03/2026 | B20: Spesa fissa marzo | C20: 100 | D20: Manuale
A21: 01/04/2026 | B21: Spesa fissa aprile | C21: 100 | D21: Manuale
A22: TOTALE | C22: =SUM(C15:C21)
A24: SUPERMERCATO / ALIMENTARI
A25: Data | B25: Descrizione | C25: Importo | D25: Fonte | E25: Pagato | F25: Note
A26: 02/10/2025 | B26: COOP Foligno | C26: 10.04 | D26: Banca
A27: 05/10/2025 | B27: COOP Foligno | C27: 80.85 | D27: Banca
A28: 06/10/2025 | B28: MAURY'S Foligno | C28: 39.28 | D28: Banca
A29: 10/10/2025 | B29: PIZZERIA MANCINI Foligno | C29: 4.9 | D29: Banca
A30: 15/10/2025 | B30: MAURY'S Foligno | C30: 27.13 | D30: Banca
A31: 15/10/2025 | B31: EUROSPIN Foligno | C31: 62.15 | D31: Banca
A32: 18/10/2025 | B32: INCOOP Roccastrada | C32: 23.43 | D32: Banca
A33: 22/10/2025 | B33: COOP Foligno | C33: 40.64 | D33: Banca
A34: 22/10/2025 | B34: TODIS Foligno | C34: 17.9 | D34: Banca
A35: 22/10/2025 | B35: COOP Foligno | C35: 11.9 | D35: Banca
A36: 30/10/2025 | B36: UNICOOP ETRURIA Foligno | C36: 69.18 | D36: Banca
A37: 31/10/2025 | B37: Parmigiano (bonifico) | C37: 105 | D37: Banca
... A67: 06/04/2026 | B67: GALA | C67: 2.58 | D67: Screenshot
A68: TOTALE | C68: =SUM(C26:C67)
A70: VERDURE MATTIA BRUNI (PayPal)
A71: Data | B71: Descrizione | C71: Importo | D71: Fonte | E71: Pagato | F71: Note
A72: 16/09/2025 | B72: Mattia Bruni - verdure | C72: 35.5 | D72: PayPal
A73: 24/09/2025 | B73: Mattia Bruni - verdure | C73: 18.7 | D73: PayPal
...

Sheet Spese Personali
A1: SPESE PERSONALI ALEX (non da dividere)
A3: VIAGGIO MILANO (21-22 Gen)
A4: Data | B4: Descrizione | C4: Importo | D4: Fonte | E4: Note
A5: 21/01/2026 | B5: EXAL SRL hotel Milano | C5: 9.5 | D5: Banca
A6: TOTALE | C6: =SUM(C5)
A8: CARBURANTE (quotidiano)
A9: Data | B9: Descrizione | C9: Importo | D9: Fonte | E9: Note
A10: 03/10/2025 | B10: Distributore Ponte San Giovanni | C10: 12.63 | D10: Banca
A11: 16/10/2025 | B11: PV4894 Foligno | C11: 17.45 | D11: Banca
A12: 18/10/2025 | B12: B.D.S. AGIP Rapolano Terme | C12: 9.12 | D12: Banca
A13: 19/10/2025 | B13: IP PV 43656 Perugia | C13: 12.6 | D13: Banca
A14: 27/10/2025 | B14: Kuwait Petroleum Bastia Umbra | C14: 20.3 | D14: Banca
A15: 31/10/2025 | B15: Q8 Cioccoloni Bastia Umbra | C15: 15.5 | D15: Banca
A16: 05/11/2025 | B16: PV4894 Foligno | C16: 17.94 | D16: Banca
A17: 14/11/2025 | B17: Q8 Cioccoloni Bastia Umbra | C17: 16 | D17: Banca
A18: 19/11/2025 | B18: IP PV 43656 Perugia | C18: 15.4 | D18: Banca
A19: 27/11/2025 | B19: 47748 Foligno | C19: 30.03 | D19: Banca
A20: 28/11/2025 | B20: Stazione Servizio Trevi | C20: 19.8 | D20: Banca
A21: 06/12/2025 | B21: Automigliorgas Perugia | C21: 21.9 | D21: Banca
... A28: 06/04/2026 | B28: Q8 Cioccoloni | C28: 21.12 | D28: Screenshot
A29: TOTALE | C29: =SUM(C10:C28)
A31: SALUTE / FARMACIA
A32: Data | B32: Descrizione | C32: Importo | D32: Fonte | E32: Note
A33: 07/10/2025 | B33: AFAM SPA Foligno | C33: 26 | D33: Banca
A34: 13/10/2025 | B34: Dott Studio Medico Perugia | C34: 180 | D34: Banca
A35: 17/10/2025 | B35: Farmacia Bartoli Foligno | C35: 68.9 | D35: Banca
A36: 28/10/2025 | B36: Farmacia AFAS Perugia | C36: 19.9 | D36: Banca
A37: 28/10/2025 | B37: Rimborso farmacia (entrata) | C37: -40 | D37: Banca
A38: 12/11/2025 | B38: Farmacia Pimpinelli Magione | C38: 28 | D38: Banca
A39: 19/11/2025 | B39: Dott Studio Medico Perugia | C39: 180 | D39: Banca
A40: 27/11/2025 | B40: Farmacie Peppoloni Foligno | C40: 15 | D40: Banca
A41: 08/01/2026 | B41: Farmacia Bartoli SRL Foligno | C41: 5.9 | D41: Banca
A42: 26/01/2026 | B42: Farmacia San Vito (PayPal) | C42: 89.66 | D42: PayPal
A43: 26/01/2026 | B43: FarmaSave (PayPal) | C43: 79.18 | D43: PayPal
A44: TOTALE | C44: =SUM(C33:C43)
A46: AUTO / TRASPORTI
A47: Data | B47: Descrizione | C47: Importo | D47: Fonte | E47: Note
A48: 03/10/2025 | B48: PE.SA. Gomme Perugia | C48: 15 | D48: Banca
A49: 25/01/2026 | B49: Tasse/bollo PagoPA | C49: 114.26 | D49: Banca
A50: 27/01/2026 | B50: Tasse/bollo PagoPA Banca Sella | C50: 144.52 | D50: Banca
...

Sheet Bonifici
A1: BONIFICI TRA ALEX E BLAKE
A3: BONIFICI INVIATI A BLAKE (uscite)
A4: Data | B4: Descrizione | C4: Importo | D4: Fonte | E4: Note
A5: 30/01/2026 | B5: Per le spese della micia | C5: 50 | D5: Banca
A6: 22/02/2026 | B6: Per la mia micia | C6: 20 | D6: Banca
A7: 12/03/2026 | B7: Pio Pio | C7: 80 | D7: Banca
A8: 03/11/2025 | B8: Alex Sample, Blake Sample | C8: -280 | D8: Banca
A9: 21/03/2026 | B9: BLAKE SAMPLE | C9: -500 | D9: Banca
A10: 24/02/2026 | B10: FOR MY LADY | C10: -50 | D10: Banca
A11: TOTALE | C11: =SUM(C5:C10)
A13: BONIFICI RICEVUTI DA BLAKE (entrate)
A14: Data | B14: Descrizione | C14: Importo | D14: Fonte | E14: Note
A15: 19/11/2025 | B15: affitto e spese | C15: 500 | D15: Banca
A16: 20/11/2025 | B16: UNICO RAGAZZO CHE CHIEDE I SOLDI ALLA TIPA | C16: 210 | D16: Banca
A17: 07/11/2025 | B17: BENEFICIENZA BAMBINO POVERO DA SUGAR MOMMYY | C17: 150 | D17: Banca
A18: 10/11/2025 | B18: LADRO | C18: 400 | D18: Banca
A19: 24/03/2026 | B19: DALLA SUGAR MAMI:)) | C19: 500 | D19: Banca
A20: 24/03/2026 | B20: X PIZZA PERCHE NON SONO BRAVA MOGLIE:( | C20: 10 | D20: Banca
A21: 26/01/2026 | B21: SPESA | C21: 16.27 | D21: Banca
A22: 16/01/2026 | B22: pulizia giardino | C22: 40 | D22: Banca
A23: 16/02/2026 | B23: Rimborso Regalo | C23: 80 | D23: Banca
A24: 01/04/2026 | B24: Bonifico ricevuto - Spese | C24: 300 | D24: Screenshot
A25: TOTALE | C25: =SUM(C15:C24)
A28: Totale inviato a Blake | C28: =C11
A29: Totale ricevuto da Blake | C29: =C25
A30: NETTO ricevuto da Blake | C30: =C29+C28

Sheet Riepilogo Finale
A1: RIEPILOGO DIVISIONE SPESE
A2: Percentuali: | C2: 0.7 | D2: 0.3
A4: Categoria | B4: Totale | C4: ="Quota Alex ("&TEXT(C2,"0%")&")" | D4: ="Quota Blake ("&TEXT(D2,"0%")&")"
A5: AFFITTO | B5: ='Spese Condivise'!C11 | C5: =B5*C$2 | D5: =B5*D$2
A6: SPESA FISSA MENSILE (100 EUR/mese) | B6: ='Spese Condivise'!C22 | C6: =B6*C$2 | D6: =B6*D$2
A7: SUPERMERCATO / ALIMENTARI | B7: ='Spese Condivise'!C68 | C7: =B7*C$2 | D7: =B7*D$2
A8: VERDURE MATTIA BRUNI (PayPal) | B8: ='Spese Condivise'!C91 | C8: =B8*C$2 | D8: =B8*D$2
A9: KORO ALIMENTARI (PayPal) | B9: ='Spese Condivise'!C100 | C9: =B9*C$2 | D9: =B9*D$2
A10: MANDORLE / NOCCIOLE (forfettario) | B10: ='Spese Condivise'!C105 | C10: =B10*C$2 | D10: =B10*D$2
A11: BOLLETTE / UTENZE | B11: ='Spese Condivise'!C124 | C11: =B11*C$2 | D11: =B11*D$2
A12: CASA / ARREDAMENTO | B12: ='Spese Condivise'!C141 | C12: =B12*C$2 | D12: =B12*D$2
A13: VIAGGI - NAPOLI/ROMA (11-12 Ott) | B13: ='Spese Condivise'!C161 | C13: =B13*C$2 | D13: =B13*D$2
A14: VIAGGI - PISA (29 Nov) | B14: ='Spese Condivise'!C174 | C14: =B14*C$2 | D14: =B14*D$2
A15: VIAGGI - SESTOLA SCI (27-29 Dic) | B15: ='Spese Condivise'!C193 | C15: =B15*C$2 | D15: =B15*D$2
A16: VIAGGI - VOLI/PRENOTAZIONI | B16: ='Spese Condivise'!C198 | C16: =B16*C$2 | D16: =B16*D$2
A17: RISTORANTI / BAR (locale) | B17: ='Spese Condivise'!C211 | C17: =B17*C$2 | D17: =B17*D$2
A18: AMAZON (vari - per casa?) | B18: ='Spese Condivise'!C255 | C18: =B18*C$2 | D18: =B18*D$2
A19: SPETTACOLI / CINEMA | B19: ='Spese Condivise'!C260 | C19: =B19*C$2 | D19: =B19*D$2
A20: TECNOLOGIA / ELETTRONICA (condivisa) | B20: ='Spese Condivise'!C268 | C20: =B20*C$2 | D20: =B20*D$2
A21: ANIMALI / MICIA (condivisa) | B21: ='Spese Condivise'!C274 | C21: =B21*C$2 | D21: =B21*D$2
A22: ACQUISTI VARI (condivisi) | B22: ='Spese Condivise'!C287 | C22: =B22*C$2 | D22: =B22*D$2
A23: GOOGLE PLAY APPS | B23: ='Spese Condivise'!C297 | C23: =B23*C$2 | D23: =B23*D$2
A24: Eliminazione Amazon, tecnologia, acquisti vari | B24: =-(B18+B20+B22+B12)
A25: TOTALE SPESE CONDIVISE | B25: =SUM(B5:B24) | C25: =B25*C2 | D25: =B25*D2
A28: CALCOLO FINALE
A30: Blake deve a Alex (quota spese condivise) | B30: =D25
A31: Blake ha gia' dato a Alex (bonifici) | B31: ='Bonifici Blake'!C25
A32: Alex ha inviato a Blake (bonifici) | B32: =ABS('Bonifici Blake'!C11)
A34: BLAKE DEVE ANCORA A ALEX | B34: =B30-B31+B32
A36: NOTA: Questo calcolo non tiene conto delle spese segnate come 'Pagato=SI'
A37: nel foglio 'Spese Condivise'. Aggiorna manualmente se necessario.
